Workbook

Sheet Client-Mas-Names
A1: =IFERROR(__xludf.DUMMYFUNCTION("IMPORTRANGE(""1nXhG9zoD3F4ppV4_PoNIKqbOYdLgnLJyE2LlTlfnbOk"", ""Clients!C3:C"")"),"Client") -> Client | B1: =IFERROR(__xludf.DUMMYFUNCTION("IMPORTRANGE(""1nXhG9zoD3F4ppV4_PoNIKqbOYdLgnLJyE2LlTlfnbOk"", ""Clients!E3:E"")"),"Billing Name") -> Billing Name
A2: =IFERROR(__xludf.DUMMYFUNCTION("""COMPUTED_VALUE"""),"Office Monthly Meeting") -> Office Monthly Meeting
A3: =IFERROR(__xludf.DUMMYFUNCTION("""COMPUTED_VALUE"""),"Office (R&D,Testing)") -> Office (R&D,Testing)
A4: =IFERROR(__xludf.DUMMYFUNCTION("""COMPUTED_VALUE"""),"Vinod Lunia-SB Colony") -> Vinod Lunia-SB Colony
A5: =IFERROR(__xludf.DUMMYFUNCTION("""COMPUTED_VALUE"""),"Alagappan - Central Studio Road") -> Alagappan - Central Studio Road
A6: =IFERROR(__xludf.DUMMYFUNCTION("""COMPUTED_VALUE"""),"Samanth Bajaj-Tirupur") -> Samanth Bajaj-Tirupur
A7: =IFERROR(__xludf.DUMMYFUNCTION("""COMPUTED_VALUE"""),"Raja-Ganapathy") -> Raja-Ganapathy
A8: =IFERROR(__xludf.DUMMYFUNCTION("""COMPUTED_VALUE"""),"Manimaran - Namakkal") -> Manimaran - Namakkal
A9: =IFERROR(__xludf.DUMMYFUNCTION("""COMPUTED_VALUE"""),"Ponnusamy - Namakkal") -> Ponnusamy - Namakkal
A10: =IFERROR(__xludf.DUMMYFUNCTION("""COMPUTED_VALUE"""),"Selvakumar-Karur") -> Selvakumar-Karur
A11: =IFERROR(__xludf.DUMMYFUNCTION("""COMPUTED_VALUE"""),"Prabhuram-S B Colony") -> Prabhuram-S B Colony
A12: =IFERROR(__xludf.DUMMYFUNCTION("""COMPUTED_VALUE"""),"Raman - Ramanathapuram") -> Raman - Ramanathapuram
A13: =IFERROR(__xludf.DUMMYFUNCTION("""COMPUTED_VALUE"""),"Saranya Rajkumar-Hopes") -> Saranya Rajkumar-Hopes
A14: =IFERROR(__xludf.DUMMYFUNCTION("""COMPUTED_VALUE"""),"Dhanalakshmi - Lakshmi Mills") -> Dhanalakshmi - Lakshmi Mills
A15: =IFERROR(__xludf.DUMMYFUNCTION("""COMPUTED_VALUE"""),"Dhanakottiram - Gobi") -> Dhanakottiram - Gobi
A16: =IFERROR(__xludf.DUMMYFUNCTION("""COMPUTED_VALUE"""),"Dr.Kumaresh-Gobi") -> Dr.Kumaresh-Gobi
A17: =IFERROR(__xludf.DUMMYFUNCTION("""COMPUTED_VALUE"""),"Jai Elangovan-Coonor") -> Jai Elangovan-Coonor
A18: =IFERROR(__xludf.DUMMYFUNCTION("""COMPUTED_VALUE"""),"Dr. Prabhu-CBE") -> Dr. Prabhu-CBE
A19: =IFERROR(__xludf.DUMMYFUNCTION("""COMPUTED_VALUE"""),"Abirami-Sangagiri") -> Abirami-Sangagiri
A20: =IFERROR(__xludf.DUMMYFUNCTION("""COMPUTED_VALUE"""),"Bipin-Tirupur") -> Bipin-Tirupur
A21: =IFERROR(__xludf.DUMMYFUNCTION("""COMPUTED_VALUE"""),"Sarayu - Tirupur") -> Sarayu - Tirupur
A22: =IFERROR(__xludf.DUMMYFUNCTION("""COMPUTED_VALUE"""),"Arumugam-PSG Hospital") -> Arumugam-PSG Hospital
A23: =IFERROR(__xludf.DUMMYFUNCTION("""COMPUTED_VALUE"""),"Sumanth Ramamoorthy-ELGI") -> Sumanth Ramamoorthy-ELGI
A24: =IFERROR(__xludf.DUMMYFUNCTION("""COMPUTED_VALUE"""),"Nirmal - Salem") -> Nirmal - Salem
A25: =IFERROR(__xludf.DUMMYFUNCTION("""COMPUTED_VALUE"""),"Jayakumar-Chinthamanipudur") -> Jayakumar-Chinthamanipudur
A26: =IFERROR(__xludf.DUMMYFUNCTION("""COMPUTED_VALUE"""),"Dr.Arun-KMCH") -> Dr.Arun-KMCH
A27: =IFERROR(__xludf.DUMMYFUNCTION("""COMPUTED_VALUE"""),"Joseph Kurian (Ashik)-Cbe") -> Joseph Kurian (Ashik)-Cbe
A28: =IFERROR(__xludf.DUMMYFUNCTION("""COMPUTED_VALUE"""),"Dr.Thiyagararjan - Ram Nagar") -> Dr.Thiyagararjan - Ram Nagar
A29: =IFERROR(__xludf.DUMMYFUNCTION("""COMPUTED_VALUE"""),"Selvaraj - Salem") -> Selvaraj - Salem
A30: =IFERROR(__xludf.DUMMYFUNCTION("""COMPUTED_VALUE"""),"Arun-Mettupalayam") -> Arun-Mettupalayam
A31: =IFERROR(__xludf.DUMMYFUNCTION("""COMPUTED_VALUE"""),"Nandhakumar - V'Koil") -> Nandhakumar - V'Koil
A32: =IFERROR(__xludf.DUMMYFUNCTION("""COMPUTED_VALUE"""),"Anoop Shroff - S B Colony") -> Anoop Shroff - S B Colony
A33: =IFERROR(__xludf.DUMMYFUNCTION("""COMPUTED_VALUE"""),"Krishnaveni - Tirupur") -> Krishnaveni - Tirupur
A34: =IFERROR(__xludf.DUMMYFUNCTION("""COMPUTED_VALUE"""),"Subburaj-Vadavali") -> Subburaj-Vadavali
A35: =IFERROR(__xludf.DUMMYFUNCTION("""COMPUTED_VALUE"""),"Selvaraj-Vadavali") -> Selvaraj-Vadavali
A36: =IFERROR(__xludf.DUMMYFUNCTION("""COMPUTED_VALUE"""),"Ramamorthy-Karamadai") -> Ramamorthy-Karamadai
A37: =IFERROR(__xludf.DUMMYFUNCTION("""COMPUTED_VALUE"""),"L N House - Race Course") -> L N House - Race Course
A38: =IFERROR(__xludf.DUMMYFUNCTION("""COMPUTED_VALUE"""),"Suresh (CVS) - Pollachi") -> Suresh (CVS) - Pollachi
A39: =IFERROR(__xludf.DUMMYFUNCTION("""COMPUTED_VALUE"""),"Mr. Prabhakaran") -> Mr. Prabhakaran
A40: =IFERROR(__xludf.DUMMYFUNCTION("""COMPUTED_VALUE"""),"Dinesh Anand-Vadavalli") -> Dinesh Anand-Vadavalli
...

Sheet BOM Overview
I1: Customer approval pending | J1: Inka side pending | K1: Inka side pending | L1: Inka side pending | M1: Inka side pending | O1: Ok | Q1: Inka service pending | R1: Inka service pending | S1: Inka service pending | U1: Ok
C2: Client Name | D2: Vijayalakshmi - Palladam | E2: Estimate BOM | F2: Addl./Subtract | G2: Total | H2: Zoho Bom | I2: Awaiting order request | J2: To order material | K2: Ordered | L2: Recd (To test/config) | M2: Configured - ready for install | N2: Inka Side Pending | O2: Delivered | P2: Provision only - Matl Not reqd | Q2: Failed - Picked up from site | R2: Failed - Need to service | S2: Sent for service | T2: Inka Service Pending | U2: Replaced/Serviced | V2: Returned - Not reqd
H3: (From DCs in Zoho)
A4: camera | B4: Brand | C4: Product | D4: Model No
B5: WBOX | C5: {=unique('Apex-Vedapatti'!C17:C88)} -> #REF! | D5: 12312as | E5: =countif('Apex-Vedapatti '!C$18:C$106,C5) -> 0
E6: =countif('Apex-Vedapatti '!C$18:C$106,C6) -> 0
E7: =countif('Apex-Vedapatti '!C$18:C$106,C7) -> 0 | I7: 1
E8: =countif('Apex-Vedapatti '!C$18:C$106,C8) -> 0
E9: =countif('Apex-Vedapatti '!C$18:C$106,C9) -> 0
E10: =countif('Apex-Vedapatti '!C$18:C$106,C10) -> 0
E11: =countif('Apex-Vedapatti '!C$18:C$106,C11) -> 0 | I11: API for pulling DCs
E12: =countif('Apex-Vedapatti '!C$18:C$106,C12) -> 0 | I12: https://books.zoho.com/api/v3/deliverychallans?organization_id=65760XXX7
E13: =countif('Apex-Vedapatti '!C$18:C$106,C13) -> 0
E14: =countif('Apex-Vedapatti '!C$18:C$106,C14) -> 0
E15: =countif('Apex-Vedapatti '!C$18:C$106,C15) -> 0 | I15: 3 | L15: 2 | M15: 1 | N15: 3
E16: =countif('Apex-Vedapatti '!C$18:C$106,C16) -> 0
E17: =countif('Apex-Vedapatti '!C$18:C$106,C17) -> 0
E18: =countif('Apex-Vedapatti '!C$18:C$106,C18) -> 0
E19: =countif('Apex-Vedapatti '!C$18:C$106,C19) -> 0
E20: =countif('Apex-Vedapatti '!C$18:C$106,C20) -> 0
E21: =countif('Apex-Vedapatti '!C$18:C$106,C21) -> 0
E22: =countif('Apex-Vedapatti '!C$18:C$106,C22) -> 0
E23: =countif('Apex-Vedapatti '!C$18:C$106,C23) -> 0
E24: =countif('Apex-Vedapatti '!C$18:C$106,C24) -> 0
E25: =countif('Apex-Vedapatti '!C$18:C$106,C25) -> 0
E26: =countif('Apex-Vedapatti '!C$18:C$106,C26) -> 0
E27: =countif('Apex-Vedapatti '!C$18:C$106,C27) -> 0

Sheet ClientProjects List
B1: Sheet No. | C1: Client Name | D1: Site | E1: Eng. in Charge of BOM | F1: Link | G1: G-Drive Link (Drawings & BOM) | H1: Site Status | I1: Site Status | J1: Provisions | K1: BOM | L1: Remarks | M1: Stage 1- Visit Counts needed | N1: Stage 2 - Visit Counts needed | O1: Visited count Stage 1 | P1: Visited count stage 2 | Q1: % work completed | R1: As on
A2: Vijalakshmi - Palladam | C2: Vijayalakshmi | D2: Palladam | E2: Sakthi | F2: Vijayalakshmi | G2: https://drive.google.com/open?id=13cvRfsalE__mU8atlx5vs60QfmFuhd6g | L2: Except SS all materials ready
A3: Dr.Karthik-Mettupalayam | B3: 49 | C3: Karthik | D3: Mettupalayam | E3: Sakthi | F3: Dr. Karthik
A4: Suresh Prabhagaran-salem | B4: 81 | C4: Suresh | D4: Salem | F4: Suresh Prabhagaran
A5: Karthikeyan-Tirupur | B5: 105 | C5: Karthikeyan | D5: Tirupur | E5: Sakthi | F5: Karthikeyan
A6: Shan Vembutty | B6: 107 | C6: Sudarshan | D6: Chettipalayam | E6: Asok | F6: Sudarshan
A7: Vanji-NavIndia | B7: 121 | C7: Vanji | D7: Nav India | E7: Asok | F7: Vanji | R7: 13.3.2024
B8: 135 | C8: Srinivasan | D8: Tirupur | E8: Sakthi | F8: Srinivasan
A9: Ar. Mohanraj | B9: 136 | C9: Mohanraj | D9: Coimbatore | E9: Sakthi | F9: Ar. Mohanraj
A10: Prabhu-Palladam | B10: 142 | C10: Prabhu | D10: Palladam | E10: Asok | F10: Prabhu | R10: 18.2.2024
A11: Vijayabharathi-Palani | B11: 144 | C11: Vijayabharathi | D11: Palani | E11: Pistis | F11: Vijayabharathi
A12: Ar.Sathiya | B12: 146 | C12: Sathiya | D12: Saravanampatti | E12: Asok | F12: Madblack
A13: ALC | B13: 147 | C13: Arthanari | D13: Salem | E13: Asok | F13: ALC
A14: Prabhu-Tirupur | B14: 148 | C14: Prabhu | D14: Tirupur | E14: Asok | F14: Prabhu
A15: Dhanraj | B15: 149 | C15: Dhanraj | D15: Puliayampatti | E15: Asok | F15: Dhanraj | R15: 4.4.2024
A16: SPP Silk House-Mr Karthikeyan | B16: 152 | C16: SPP Silk House | D16: Cheran Nagar | E16: Asok | F16: SPP Silks | G16: FF - 4 Rooms - Dimming, Mobile app Additional need zmote for tata sky
A17: Chandrasekar | B17: 155 | C17: Chandrasekar | D17: Tindivanam | E17: Pistis | F17: Chandrasekar
A18: Gopalakrishnan | B18: 158 | C18: Gopalakrishnan | D18: Tirupur | E18: Sakthi | F18: Gopalakrishnan
A19: Arun Vijay | B19: 159 | C19: Arun Vijay | D19: Krishnagiri | E19: Asok | F19: Arun Vijay
A20: Punita | B20: 162 | C20: Punita | D20: Kalapatti | E20: Asok | F20: Punita | G20: Door sensor -5 Nos.
A21: Venba Residence | B21: 164 | C21: Venba | D21: Coimbatore | E21: Asok | F21: Venba | G21: Biometric pending
A22: Singaram | B22: 165 | C22: Singaram | D22: Saibaba colony | E22: Sakthi | F22: Singaram | G22: Balance payment to receive
A23: Sumanth Ramamoorthy-ELGI | B23: 192 | C23: Sumanth | D23: Race Course | E23: Asok
A24: Aarthi Residence | B24: 166 | C24: Vignesh | D24: kalapatti | E24: Asok | F24: Vignesh
A25: Manikandan-Vedasanthur | B25: 172 | C25: Manikandan | D25: Vedasanthur | E25: Asok | F25: Manikandan
A26: Shivakumar, Kothagiri | B26: 173 | C26: Shivakumar | D26: Kothagiri | E26: Asok | F26: Shivakumar
A27: Dinesh | B27: 176 | C27: Dinesh | D27: Sathyamangalam | F27: Dinesh
A28: Thirumoorthy | B28: 179 | C28: Thirumoorthy | D28: Karur | E28: Asok | F28: Thirumoorthy | G28: temporarily installed 4 cameras
A29: Karpagavalli, Namakkal | B29: 184 | C29: Karpavalli | D29: Namakkal | E29: Kumaraguru | F29: Karpagavalli
A30: Studio Mello | B30: 187 | C30: Studio Mello | D30: Salem | E30: Sakthi | F30: Studio Mello
A31: Janani (JCA Residence) | B31: 188 | C31: Janani | D31: Tirupur | E31: Sakthi | F31: Janani (JCA Residence)
A32: Aarthi Harish | B32: 190 | C32: Aarthi Harish | D32: Ganapathy | E32: Asok | F32: Aarthi Harish
A33: Senthil-Asian Pavers | B33: 193 | C33: Senthil | D33: Saravanampatti | E33: Asok | F33: Senthil
A34: Dhanabal | B34: 194 | C34: Dhanabal | D34: Gounder mills | E34: Sakthi | F34: Dhanabal
A35: Raja | B35: 195 | C35: Raja | D35: Tirupur | E35: Sakthi | F35: Raja
A36: Chandramohan | B36: 196 | C36: Chandramohan | D36: Tirupur | E36: Kumaraguru | F36: Chandramohan
A37: Gunasekar-kalapatti | B37: 198 | C37: Gunasekar | D37: Kalapatti | E37: Sakthi | F37: Gunasekar
A38: Abhishek - Abinitha | B38: 199 | C38: Abhinitha | E38: Asok | F38: Abhishek
A39: Renjith Calicut | B39: 204 | C39: Renjith | D39: Calicut | E39: Asok | F39: Renjith
A40: Pooja Summit | B40: 205 | C40: Pooja | D40: Vallukuparai | E40: Asok | F40: Pooja summit
...

Sheet Anugraha Residence
B1: Client Name | C1: Anugraha Residence | F1: Overall site status | J1: Count | K1: % | M1: Material status | N1: Count | O1: % | Q1: Visti No. | R1: IR No. | S1: Date
B2: Site | C2: Edyarpalayam | F2: Yet to start | M2: Awaiting order request | Q2: 1 | S2: 21.2.2026 | T2: 1st site visit | U2: Satheesh & Tharun
B3: Location | F3: Position marked - I | M3: To order material | Q3: 2 | S3: 23.2.2026 | T3: Site meeting | U3: Satheesh
B4: GPS Coordinates | F4: Piping done - C | M4: Ordered
B5: Architect | F5: Wiring done - C | M5: Recd (To test/config)
B6: Site Supervisor | F6: Wiring - Checked Ok - I | M6: Configured - ready for install
B7: Electrician | F7: Wiring rework reqd - C | M7: Delivered
B8: Electrical Contractor | F8: Provision not provided - C | M8: Provision only - Matl Not reqd
B9: Billing contact | F9: Position to be changed - C | M9: Failed - Picked up from site
B10: Carpenter | F10: Installed - working | M10: Failed - Need to service
B11: Civil Supervisor | F11: Installed - To activate - I | M11: Sent for service
B12: G-Drive Link | F12: Installed - Not working - IC | M12: Replaced/Serviced
B13: Mail id | F13: Door Ready - C | M13: Returned - Not reqd
B14: Site Engineer | F14: Door Not Ready - I
B15: Brand | C15: Product | D15: Serial No. | E15: Model No | F15: Sale Price | G15: Installation charge | H15: Location | I15: Drawing Ref No. | J15: Site status | K15: <--Date | L15: Prop/Addl | M15: Material | N15: <-- Date | O15: Client | P15: Inka | Q15: Comments | R15: SR Nos (If multiple - add all) | S15: DC

Sheet Kavitha
B1: Client Name | C1: Mrs. Kavitha | F1: Overall site status | J1: Count | K1: % | M1: Material status | N1: Count | O1: % | Q1: Visti No. | R1: IR No. | S1: Date
B2: Site | C2: Bangalore | F2: Yet to start | M2: Awaiting order request | Q2: 1 | S2: 15.2.2026 | T2: 1st site visit | U2: Kumaraguru
B3: Location | C3: https://www.google.com/maps?q=13.0039654,77.7405749&z=17&hl=en | F3: Position marked - I | M3: To order material | Q3: 2
B4: GPS Coordinates | F4: Piping done - C | M4: Ordered
B5: Architect | F5: Wiring done - C | M5: Recd (To test/config)
B6: Site Supervisor | F6: Wiring - Checked Ok - I | M6: Configured - ready for install
B7: Electrician | C7: Vnktsa Elctr New | E7: 91770 92700 | F7: Wiring rework reqd - C | M7: Delivered
B8: Electrical Contractor | F8: Provision not provided - C | M8: Provision only - Matl Not reqd
B9: Billing contact | F9: Position to be changed - C | M9: Failed - Picked up from site
B10: Carpenter | F10: Installed - working | M10: Failed - Need to service
B11: Civil Supervisor | F11: Installed - To activate - I | M11: Sent for service
B12: G-Drive Link | F12: Installed - Not working - IC | M12: Replaced/Serviced
B13: Mail id | F13: Door Ready - C | M13: Returned - Not reqd
B14: Site Engineer | F14: Door Not Ready - I
B15: Brand | C15: Product | D15: Serial No. | E15: Model No | F15: Sale Price | G15: Installation charge | H15: Location | I15: Drawing Ref No. | J15: Site status | K15: <--Date | L15: Prop/Addl | M15: Material | N15: <-- Date | O15: Client | P15: Inka | Q15: Comments | R15: SR Nos (If multiple - add all) | S15: DC
A16: Camera | B16: Prama Hikivision | C16: 4 MP Bullet IP Camera Colour - Prama Hikvision | E16: PT-NC140D3LIU- D1 | F16: 3950 | G16: 56890 | J16: Yet to start | K16: 15.2.2026 | L16: Prop | Q16: 1st site visit
B17: Prama Hikivision | C17: 4 MP Bullet IP Camera Colour - Prama Hikvision | E17: PT-NC140D3LIU- D1 | F17: 3950 | J17: Yet to start | K17: 15.2.2026 | L17: Prop | Q17: 1st site visit
B18: Prama Hikivision | C18: 4 MP Bullet IP Camera Colour - Prama Hikvision | E18: PT-NC140D3LIU- D1 | F18: 3950 | J18: Yet to start | K18: 15.2.2026 | L18: Prop | Q18: 1st site visit
B19: Prama Hikivision | C19: 4 MP Bullet IP Camera Colour - Prama Hikvision | E19: PT-NC140D3LIU- D1 | F19: 3950 | J19: Yet to start | K19: 15.2.2026 | L19: Prop | Q19: 1st site visit
B20: Prama Hikivision | C20: 4 MP Bullet IP Camera Colour - Prama Hikvision | E20: PT-NC140D3LIU- D1 | F20: 3950 | J20: Yet to start | K20: 15.2.2026 | L20: Prop | Q20: 1st site visit
B21: Prama Hikivision | C21: 4 MP Bullet IP Camera Colour - Prama Hikvision | E21: PT-NC140D3LIU- D1 | F21: 3950 | J21: Yet to start | K21: 15.2.2026 | L21: Prop | Q21: 1st site visit
B22: Prama Hikivision | C22: 4 MP Bullet IP Camera Colour - Prama Hikvision | E22: PT-NC140D3LIU- D1 | F22: 3950 | J22: Yet to start | K22: 15.2.2026 | L22: Prop | Q22: 1st site visit
B23: Prama Hikivision | C23: 4 MP Bullet IP Camera Colour - Prama Hikvision | E23: PT-NC140D3LIU- D1 | F23: 3950 | J23: Yet to start | K23: 15.2.2026 | L23: Prop | Q23: 1st site visit
B24: Prama Hikivision | C24: 4 MP Bullet IP Camera Colour - Prama Hikvision | E24: PT-NC140D3LIU- D1 | F24: 3950 | J24: Yet to start | K24: 15.2.2026 | L24: Prop | Q24: 1st site visit
B25: Prama Hikivision | C25: 4 MP Bullet IP Camera Colour - Prama Hikvision | E25: PT-NC140D3LIU- D1 | F25: 3950 | J25: Yet to start | K25: 15.2.2026 | L25: Prop | Q25: 1st site visit
B26: Prama Hikivision | C26: 4 MP Bullet IP Camera Colour - Prama Hikvision | E26: PT-NC140D3LIU- D1 | F26: 3950 | J26: Yet to start | K26: 15.2.2026 | L26: Prop | Q26: 1st site visit
B27: Hikvision | C27: 16 channel NVR (K2) - Hikvision | E27: DS-7616NI-K2 | F27: 15900 | J27: Yet to start | K27: 15.2.2026 | L27: Prop | Q27: 1st site visit
B28: Toshiba | C28: 4 TB Hard Disk - Toshiba | E28: AVHDDS300 | F28: 8160 | J28: Yet to start | K28: 15.2.2026 | L28: Prop | Q28: 1st site visit
... B30: TP Link | C30: 8 Port POE Switch (Gigabit) 2 Uplink SFP - TP Link | E30: TL-SG2210P | F30: 7990 | J30: Yet to start | K30: 15.2.2026 | L30: Prop | Q30: 1st site visit
C31: Camera Accessories | F31: 2500 | J31: Yet to start | K31: 15.2.2026 | L31: Prop
Q32: 1st site visit
A33: Security system | B33: Hikvision | C33: Hikvision - Control Panel Hybrid | E33: DS-PHA64-LP(B) | F33: 29500 | J33: Yet to start | K33: 15.2.2026 | L33: Prop | Q33: 1st site visit
B34: Hikvision | C34: Hikvision - GSM module | E34: DS-PM2-S | F34: 9773 | J34: Yet to start | K34: 15.2.2026 | L34: Prop | Q34: 1st site visit
B35: Hikvision | C35: Hikvision IP Module | E35: IP Module | F35: 8450 | J35: Yet to start | K35: 15.2.2026 | L35: Prop | Q35: 1st site visit
B36: Hikvision | C36: Hikvision - Wired LCD Keypad | E36: DS-PICI-LRT-HWB | F36: 7237 | J36: Yet to start | K36: 15.2.2026 | L36: Prop | Q36: 1st site visit
B37: Hikvision | C37: Hikvision Door Sensor | E37: DS-PD1-MC-WWS(H) | F37: 450 | J37: Yet to start | K37: 15.2.2026 | L37: Prop | Q37: 1st site visit
B38: Hikvision | C38: Hikvision Door Sensor | E38: DS-PD1-MC-WWS(H) | F38: 450 | J38: Yet to start | K38: 15.2.2026 | L38: Prop | Q38: 1st site visit
B39: Hikvision | C39: Hikvision Door Sensor | E39: DS-PD1-MC-WWS(H) | F39: 450 | J39: Yet to start | K39: 15.2.2026 | L39: Prop | Q39: 1st site visit
B40: Hikvision | C40: Hikvision Door Sensor | E40: DS-PD1-MC-WWS(H) | F40: 450 | J40: Yet to start | K40: 15.2.2026 | L40: Prop | Q40: 1st site visit
B41: Hikvision | C41: Hikvision Door Sensor | E41: DS-PD1-MC-WWS(H) | F41: 450 | J41: Yet to start | K41: 15.2.2026 | L41: Prop | Q41: 1st site visit
...

Sheet Chandrika Vittel
B1: Client Name | C1: Mrs.Chandrika Vittel | F1: Overall site status | J1: Count | K1: % | M1: Material status | N1: Count | O1: % | Q1: Visti No. | R1: IR No. | S1: Date
B2: Site | C2: Saibaba Colony | F2: Yet to start | M2: Awaiting order request | Q2: 1 | R2: IR No.53 | S2: 8.12.2025 | T2: 1st site visit | U2: Sakthi
B3: Location | F3: Position marked - I | M3: To order material | Q3: 2
B4: GPS Coordinates | F4: Piping done - C | M4: Ordered
B5: Architect | F5: Wiring done - C | M5: Recd (To test/config)
B6: Site Supervisor | F6: Wiring - Checked Ok - I | M6: Configured - ready for install
B7: Electrician | F7: Wiring rework reqd - C | M7: Delivered
B8: Electrical Contractor | F8: Provision not provided - C | M8: Provision only - Matl Not reqd
B9: Billing contact | F9: Position to be changed - C | M9: Failed - Picked up from site
B10: Carpenter | F10: Installed - working | M10: Failed - Need to service
B11: Civil Supervisor | F11: Installed - To activate - I | M11: Sent for service
B12: G-Drive Link | F12: Installed - Not working - IC | M12: Replaced/Serviced
B13: Mail id | F13: Door Ready - C | M13: Returned - Not reqd
B14: Site Engineer | F14: Door Not Ready - I
B15: Brand | C15: Product | D15: Serial No. | E15: Model No | F15: Sale Price | G15: Installation charge | H15: Location | I15: Drawing Ref No. | J15: Site status | K15: <--Date | L15: Prop/Addl | M15: Material | N15: <-- Date | O15: Client | P15: Inka | Q15: Comments | R15: SR Nos (If multiple - add all) | S15: DC
A16: Camera | B16: CP Plus | C16: 4 Mp Bullet IP Camera Colour/InbuiltMic -CP PLUS | E16: CP-UNC-TA41PL3C-D-LQ-0360 | F16: 4860 | G16: 11000 | L16: Prop
B17: CP Plus | C17: 4 Mp Bullet IP Camera Colour/InbuiltMic -CP PLUS | E17: CP-UNC-TA41PL3C-D-LQ-0360 | F17: 4860 | L17: Prop
B18: CP Plus | C18: 4 Mp Bullet IP Camera Colour/InbuiltMic -CP PLUS | E18: CP-UNC-TA41PL3C-D-LQ-0360 | F18: 4860 | L18: Prop
B19: CP Plus | C19: 4 Mp Bullet IP Camera Colour/InbuiltMic -CP PLUS | E19: CP-UNC-TA41PL3C-D-LQ-0360 | F19: 4860 | L19: Prop
B20: CP Plus | C20: 4 Mp Bullet IP Camera Colour/InbuiltMic -CP PLUS | E20: CP-UNC-TA41PL3C-D-LQ-0360 | F20: 4860 | L20: Prop
B21: CP Plus | C21: 4 Mp Bullet IP Camera Colour/InbuiltMic -CP PLUS | E21: CP-UNC-TA41PL3C-D-LQ-0360 | F21: 4860 | L21: Prop
B22: CP Plus | C22: 4 Mp Bullet IP Camera Colour/InbuiltMic -CP PLUS | E22: CP-UNC-TA41PL3C-D-LQ-0360 | F22: 4860 | L22: Prop
B23: CP Plus | C23: 4 Mp Bullet IP Camera Colour/InbuiltMic -CP PLUS | E23: CP-UNC-TA41PL3C-D-LQ-0360 | F23: 4860 | L23: Prop
B24: CP Plus | C24: 4 MP DOME CAMERA -CP PLUS | E24: CP-UNC-DA41L3C-D-LQ-60 | F24: 4450 | L24: Prop
B25: CP Plus | C25: 16 Channel NVR (2 Sata) - CP Plus | E25: CP-UNR-4K2162/V2 | F25: 20450 | L25: Prop
B26: TP Link | C26: 16 Port POE Gigabit Switch (TL-SG1218MPE) - TP Link | E26: TL-SG1218MPE | F26: 17500 | L26: Prop
B27: WBOX | C27: 8 TB Hard Disk - WD | E27: NIL | F27: 17980 | L27: Prop
C28: Camera Accessories | F28: 2500 | L28: Prop

Sheet Prithivi
B1: Client Name | C1: Mr.Prithivi | F1: Overall site status | J1: Count | K1: % | M1: Material status | N1: Count | O1: % | Q1: Visti No. | R1: IR No. | S1: Date
B2: Site | C2: Coimbatore | F2: Yet to start | M2: Awaiting order request | Q2: 1 | R2: IR No.1448 | S2: 1.12.2025 | T2: 1st site visit | U2: Asok & Kumaraguru
B3: Location | F3: Position marked - I | M3: To order material | Q3: 2
B4: GPS Coordinates | F4: Piping done - C | M4: Ordered
B5: Architect | F5: Wiring done - C | M5: Recd (To test/config)
B6: Site Supervisor | F6: Wiring - Checked Ok - I | M6: Configured - ready for install
B7: Electrician | F7: Wiring rework reqd - C | M7: Delivered
B8: Electrical Contractor | F8: Provision not provided - C | M8: Provision only - Matl Not reqd
B9: Billing contact | F9: Position to be changed - C | M9: Failed - Picked up from site
B10: Carpenter | F10: Installed - working | M10: Failed - Need to service
B11: Civil Supervisor | F11: Installed - To activate - I | M11: Sent for service
B12: G-Drive Link | F12: Installed - Not working - IC | M12: Replaced/Serviced
B13: Mail id | F13: Door Ready - C | M13: Returned - Not reqd
B14: Site Engineer | F14: Door Not Ready - I
B15: Brand | C15: Product | D15: Product | E15: Model No | F15: Sale Price | G15: Installation charge | H15: Location | I15: Drawing Ref No. | J15: Site status | K15: <--Date | L15: Prop/Addl | M15: Material | N15: <-- Date | O15: Client | P15: Inka | Q15: Comments | R15: SR Nos (If multiple - add all) | S15: DC
A16: Automation | B16: KNX | C16: KNX Power Supply 640mA

Sheet Shruthinith
B1: Client Name | C1: Mr.Shruthinith | E1: 9363600603 | F1: Overall site status | J1: Count | K1: % | M1: Material status | N1: Count | O1: % | Q1: Visti No. | R1: IR No. | S1: Date
B2: Site | C2: Coimbatore | F2: Yet to start | M2: Awaiting order request | Q2: 1 | R2: IR No.1473 | S2: 30.1.2026 | T2: 1st site visit | U2: Kumaraguru
B3: Location | F3: Position marked - I | M3: To order material | Q3: 2
B4: GPS Coordinates | F4: Piping done - C | M4: Ordered
B5: Architect | F5: Wiring done - C | M5: Recd (To test/config)
B6: Site Supervisor | F6: Wiring - Checked Ok - I | M6: Configured - ready for install
B7: Electrician | C7: Mr.Shanmugam | E7: 9566955892 | F7: Wiring rework reqd - C | M7: Delivered
B8: Electrical Contractor | F8: Provision not provided - C | M8: Provision only - Matl Not reqd
B9: Billing contact | F9: Position to be changed - C | M9: Failed - Picked up from site
B10: Carpenter | F10: Installed - working | M10: Failed - Need to service
B11: Civil Supervisor | F11: Installed - To activate - I | M11: Sent for service
B12: G-Drive Link | F12: Installed - Not working - IC | M12: Replaced/Serviced
B13: Mail id | F13: Door Ready - C | M13: Returned - Not reqd
B14: Site Engineer | F14: Door Not Ready - I
B15: Brand | C15: Product | D15: Serial No. | E15: Model No | F15: Sale Price | G15: Installation charge | H15: Location | I15: Drawing Ref No. | J15: Site status | K15: <--Date | L15: Prop/Addl | M15: Material | N15: <-- Date | O15: Client | P15: Inka | Q15: Comments | R15: SR Nos (If multiple - add all) | S15: DC
A16: Camera | B16: Hikvision | C16: 4 MP Bullet IP Camera (3043GO-I) - Hikvision | E16: DS - 2CD1043G0-I - 4mm | F16: 6450 | G16: 11401 | L16: Prop
B17: Hikvision | C17: 4 MP Bullet IP Camera (3043GO-I) - Hikvision | E17: DS - 2CD1043G0-I - 4mm | F17: 6450 | L17: Prop
B18: Hikvision | C18: 4 MP Bullet IP Camera (3043GO-I) - Hikvision | E18: DS - 2CD1043G0-I - 4mm | F18: 6450 | L18: Prop
B19: Hikvision | C19: 4 MP Bullet IP Camera (3043GO-I) - Hikvision | E19: DS - 2CD1043G0-I - 4mm | F19: 6450 | L19: Prop
B20: Hikvision | C20: 4 MP Bullet IP Camera (3043GO-I) - Hikvision | E20: DS - 2CD1043G0-I - 4mm | F20: 6450 | L20: Prop
B21: Hikvision | C21: 4 MP Bullet IP Camera (3043GO-I) - Hikvision | E21: DS - 2CD1043G0-I - 4mm | F21: 6450 | L21: Prop
B22: Hikvision | C22: 4 MP Bullet IP Camera (3043GO-I) - Hikvision | E22: DS - 2CD1043G0-I - 4mm | F22: 6450 | L22: Prop
B23: Hikvision | C23: 4 MP Bullet IP Camera (3043GO-I) - Hikvision | E23: DS - 2CD1043G0-I - 4mm | F23: 6450 | L23: Prop
B24: Hikvision | C24: 4 MP Bullet IP Camera (3043GO-I) - Hikvision | E24: DS - 2CD1043G0-I - 4mm | F24: 6450 | L24: Prop
B25: Hikvision | C25: 4 MP Bullet IP Camera (3043GO-I) - Hikvision | E25: DS - 2CD1043G0-I - 4mm | F25: 6450 | L25: Prop
B26: Hikvision | C26: 4 MP Bullet IP Camera (3043GO-I) - Hikvision | E26: DS - 2CD1043G0-I - 4mm | F26: 6450 | L26: Prop
B27: Hikvision | C27: 4 MP Bullet IP Camera (3043GO-I) - Hikvision | E27: DS - 2CD1043G0-I - 4mm | F27: 6450 | L27: Prop
B28: Hikvision | C28: 4 MP Bullet IP Camera (3043GO-I) - Hikvision | E28: DS - 2CD1043G0-I - 4mm | F28: 6450 | L28: Prop
B29: Hikvision | C29: 16 channel NVR (K2) - Hikvision | E29: DS-7616NI-K2 | F29: 15900
B30: TP Link | C30: 8 Port POE Switch (Gigabit) 2 Uplink SFP - TP Link | E30: TL-SG2210P | F30: 8250
B31: TP Link | C31: 8 Port POE Switch (Gigabit) 2 Uplink SFP - TP Link | E31: TL-SG2210P | F31: 8250
B32: Toshiba | C32: 4 TB Hard Disk - Toshiba | E32: AVHDDS300 | F32: 8160
C33: Camera Accessories | F33: 2500
A35: Wifi | B35: TP Link | C35: Access Point EAP245 - TP Link | E35: EAP245 | F35: 8250 | G35: 4125
B36: TP Link | C36: Access Point EAP245 - TP Link | E36: EAP245 | F36: 8250
B37: TP Link | C37: Access Point EAP245 - TP Link | E37: EAP245 | F37: 8250
B38: TP Link | C38: Access Point EAP245 - TP Link | E38: EAP245 | F38: 8250
B39: TP Link | C39: Access Point EAP245 - TP Link | E39: EAP245 | F39: 8250
A41: Video Door Phone System - Hikvision | B41: Hikvision | C41: VDP Outdoor Camera - Hikvision | E41: DS-KD8003-IME1/Surface | F41: 11600 | G41: 2603
B42: Hikvision | C42: VDP Indoor Monitor - Hikvision | E42: DS-KH6320-WTE1 | F42: 10480
...

Sheet Christopher
B1: Client Name | C1: Mr.Christopher | E1: 9994588885 | F1: Overall site status | J1: Count | K1: % | M1: Material status | N1: Count | O1: % | Q1: Visti No. | R1: IR No. | S1: Date
B2: Site | C2: Coimbatore | F2: Yet to start | M2: Awaiting order request | Q2: 1 | R2: IR No.1448 | S2: 1.12.2025 | T2: 1st site visit | U2: Asok & Kumaraguru
B3: Location | F3: Position marked - I | M3: To order material | Q3: 2
B4: GPS Coordinates | F4: Piping done - C | M4: Ordered
B5: Architect | F5: Wiring done - C | M5: Recd (To test/config)
B6: Site Supervisor | C6: Mr.Sarathi (Dreamstyle interiors) | E6: 9600099600 | F6: Wiring - Checked Ok - I | M6: Configured - ready for install
B7: Electrician | C7: Mr.Mansoor | E7: 8344572588 | F7: Wiring rework reqd - C | M7: Delivered
B8: Electrical Contractor | F8: Provision not provided - C | M8: Provision only - Matl Not reqd
B9: Billing contact | F9: Position to be changed - C | M9: Failed - Picked up from site
B10: Carpenter | F10: Installed - working | M10: Failed - Need to service
B11: Civil Supervisor | F11: Installed - To activate - I | M11: Sent for service
B12: G-Drive Link | F12: Installed - Not working - IC | M12: Replaced/Serviced
B13: Mail id | F13: Door Ready - C | M13: Returned - Not reqd
B14: Site Engineer | F14: Door Not Ready - I
B15: Brand | C15: Product | D15: Serial No. | E15: Model No | F15: Sale Price | G15: Installation charge | H15: Location | I15: Drawing Ref No. | J15: Site status | K15: <--Date | L15: Prop/Addl | M15: Material | N15: <-- Date | O15: Client | P15: Inka | Q15: Comments | R15: SR Nos (If multiple - add all) | S15: DC
A16: Camera | B16: Prama Hikvision | C16: 4 MP Bullet IP Camera Colour - Prama Hikvision | E16: PT-NC140D3LIU- D1 | F16: 4750 | G16: 10461 | J16: Yet to start | K16: 1.12.2025 | L16: Prop | M16: Awaiting order request | R16: 1448
B17: Prama Hikvision | C17: 4 MP Bullet IP Camera Colour - Prama Hikvision | E17: PT-NC140D3LIU- D1 | F17: 4750 | J17: Yet to start | K17: 1.12.2025 | L17: Prop | M17: Awaiting order request | R17: 1448
B18: Prama Hikvision | C18: 4 MP Bullet IP Camera Colour - Prama Hikvision | E18: PT-NC140D3LIU- D1 | F18: 4750 | J18: Yet to start | K18: 1.12.2025 | L18: Prop | M18: Awaiting order request | R18: 1448
B19: Prama Hikvision | C19: 4 MP Bullet IP Camera Colour - Prama Hikvision | E19: PT-NC140D3LIU- D1 | F19: 4750 | J19: Yet to start | K19: 1.12.2025 | L19: Prop | M19: Awaiting order request | R19: 1448
B20: Prama Hikvision | C20: 4 MP Bullet IP Camera Colour - Prama Hikvision | E20: PT-NC140D3LIU- D1 | F20: 4750 | J20: Yet to start | K20: 1.12.2025 | L20: Prop | M20: Awaiting order request | R20: 1448
B21: Prama Hikvision | C21: 4 MP Bullet IP Camera Colour - Prama Hikvision | E21: PT-NC140D3LIU- D1 | F21: 4750 | J21: Yet to start | K21: 1.12.2025 | L21: Prop | M21: Awaiting order request | R21: 1448
B22: Prama Hikvision | C22: 4 MP Bullet IP Camera Colour - Prama Hikvision | E22: PT-NC140D3LIU- D1 | F22: 4750 | J22: Yet to start | K22: 1.12.2025 | L22: Prop | M22: Awaiting order request | R22: 1448
B23: Prama Hikvision | C23: 4 MP Bullet IP Camera Colour - Prama Hikvision | E23: PT-NC140D3LIU- D1 | F23: 4750 | J23: Yet to start | K23: 1.12.2025 | L23: Prop | M23: Awaiting order request | R23: 1448
B24: Prama Hikvision | C24: 4 MP Bullet IP Camera Colour - Prama Hikvision | E24: PT-NC140D3LIU- D1 | F24: 4750 | J24: Yet to start | K24: 1.12.2025 | L24: Prop | M24: Awaiting order request | R24: 1448
B25: Prama Hikvision | C25: 4 MP Bullet IP Camera Colour - Prama Hikvision | E25: PT-NC140D3LIU- D1 | F25: 4750 | J25: Yet to start | K25: 1.12.2025 | L25: Prop | M25: Awaiting order request | R25: 1448
B26: Prama Hikvision | C26: 4 MP Bullet IP Camera Colour - Prama Hikvision | E26: PT-NC140D3LIU- D1 | F26: 4750 | J26: Yet to start | K26: 1.12.2025 | L26: Prop | M26: Awaiting order request | R26: 1448
B27: Prama Hikvision | C27: 4 MP Bullet IP Camera Colour - Prama Hikvision | E27: PT-NC140D3LIU- D1 | F27: 4750 | J27: Yet to start | K27: 1.12.2025 | L27: Prop | M27: Awaiting order request | R27: 1448
B28: Prama Hikvision | C28: 4 MP Bullet IP Camera Colour - Prama Hikvision | E28: PT-NC140D3LIU- D1 | F28: 4750 | J28: Yet to start | K28: 1.12.2025 | L28: Prop | M28: Awaiting order request | R28: 1448
... B32: TP Link | C32: 8 Port POE Switch (Gigabit) 2 Uplink SFP - TP Link | E32: TL-SG2210P | F32: 8250 | J32: Yet to start | K32: 1.12.2025 | L32: Prop | M32: Awaiting order request | R32: 1448
C33: Camera Accessories | F33: 2500 | J33: Yet to start | K33: 1.12.2025 | L33: Prop | M33: Awaiting order request | R33: 1448
A35: Security Alarm System - DSC TYCO | B35: DSC | C35: DSC Hybrid - Control Panel | E35: HS2032NKCE | F35: 22450 | G35: 9196 | J35: Yet to start | K35: 1.12.2025 | L35: Prop | M35: Awaiting order request | R35: 1448
B36: DSC | C36: DSC - LCD Keypad Kit | E36: HS2LCDS | F36: 5900 | J36: Yet to start | K36: 1.12.2025 | L36: Prop | M36: Awaiting order request | R36: 1448
B37: DSC | C37: DSC - Power Supply (220V CE Transformer) | E37: 220-16.5V TRF | F37: 2808 | J37: Yet to start | K37: 1.12.2025 | L37: Prop | M37: Awaiting order request | R37: 1448
B38: Securico | C38: Door Sensor (Mag) - Wired | E38: SEC-MSC | F38: 450 | J38: Yet to start | K38: 1.12.2025 | L38: Prop | M38: Awaiting order request | R38: 1448
B39: Securico | C39: Door Sensor (Mag) - Wired | E39: SEC-MSC | F39: 450 | J39: Yet to start | K39: 1.12.2025 | L39: Prop | M39: Awaiting order request | R39: 1448
B40: Securico | C40: Door Sensor (Mag) - Wired | E40: SEC-MSC | F40: 450 | J40: Yet to start | K40: 1.12.2025 | L40: Prop | M40: Awaiting order request | R40: 1448
B41: Securico | C41: Door Sensor (Mag) - Wired | E41: SEC-MSC | F41: 450 | J41: Yet to start | K41: 1.12.2025 | L41: Prop | M41: Awaiting order request | R41: 1448
B42: Securico | C42: Door Sensor (Mag) - Wired | E42: SEC-MSC | F42: 450 | J42: Yet to start | K42: 1.12.2025 | L42: Prop | M42: Awaiting order request | R42: 1448
B43: Securico | C43: Door Sensor (Mag) - Wired | E43: SEC-MSC | F43: 450 | J43: Yet to start | K43: 1.12.2025 | L43: Prop | M43: Awaiting order request | R43: 1448
B44: Securico | C44: Door Sensor (Mag) - Wired | E44: SEC-MSC | F44: 450 | J44: Yet to start | K44: 1.12.2025 | L44: Prop | M44: Awaiting order request | R44: 1448
...

Sheet Prabhakaran
B1: Client Name | C1: Mr.Prabhakaran | E1: 9894605424 | F1: Overall site status | J1: Count | K1: % | M1: Material status | N1: Count | O1: % | Q1: Visti No. | R1: IR No. | S1: Date
B2: Site | C2: Ottanchaittram | F2: Yet to start | M2: Awaiting order request | Q2: 1 | R2: IR No.174 | S2: 8.11.2025 | T2: 1st site visit | U2: Azhagar
B3: Location | F3: Position marked - I | M3: To order material | Q3: 2
B4: GPS Coordinates | F4: Piping done - C | M4: Ordered
B5: Architect | F5: Wiring done - C | M5: Recd (To test/config)
B6: Site Supervisor | F6: Wiring - Checked Ok - I | M6: Configured - ready for install
B7: Electrician | C7: Mr.Jodheeswaran | E7: 8661867089 | F7: Wiring rework reqd - C | M7: Delivered
B8: Electrical Contractor | F8: Provision not provided - C | M8: Provision only - Matl Not reqd
B9: Billing contact | F9: Position to be changed - C | M9: Failed - Picked up from site
B10: Carpenter | F10: Installed - working | M10: Failed - Need to service
B11: Civil Supervisor | F11: Installed - To activate - I | M11: Sent for service
B12: G-Drive Link | F12: Installed - Not working - IC | M12: Replaced/Serviced
B13: Mail id | F13: Door Ready - C | M13: Returned - Not reqd
B14: Site Engineer | F14: Door Not Ready - I
B15: Brand | C15: Product | D15: Serial No. | E15: Model No | F15: Sale Price | G15: Installation charge | H15: Location | I15: Drawing Ref No. | J15: Site status | K15: <--Date | L15: Prop/Addl | M15: Material | N15: <-- Date | O15: Client | P15: Inka | Q15: Comments | R15: SR Nos (If multiple - add all) | S15: DC
A16: Camera | B16: CP Plus | C16: 4 MP Bullet IP Camera - CP Plus | E16: CP-UNC-TA41L3C- | F16: 4860 | G16: 13436 | J16: Position marked - I | L16: Prop | M16: Awaiting order request
B17: CP Plus | C17: 4 MP Bullet IP Camera - CP Plus | E17: CP-UNC-TA41L3C- | F17: 4860 | J17: Position marked - I | L17: Prop | M17: Awaiting order request
B18: CP Plus | C18: 4 MP Bullet IP Camera - CP Plus | E18: CP-UNC-TA41L3C- | F18: 4860 | J18: Position marked - I | L18: Prop | M18: Awaiting order request
B19: CP Plus | C19: 4 MP Bullet IP Camera - CP Plus | E19: CP-UNC-TA41L3C- | F19: 4860 | J19: Position marked - I | L19: Prop | M19: Awaiting order request
B20: CP Plus | C20: 4 MP Bullet IP Camera - CP Plus | E20: CP-UNC-TA41L3C- | F20: 4860 | J20: Position marked - I | L20: Prop | M20: Awaiting order request
B21: CP Plus | C21: 4 MP Bullet IP Camera - CP Plus | E21: CP-UNC-TA41L3C- | F21: 4860 | J21: Position marked - I | L21: Prop | M21: Awaiting order request
B22: CP Plus | C22: 4 MP Bullet IP Camera - CP Plus | E22: CP-UNC-TA41L3C- | F22: 4860 | J22: Position marked - I | L22: Prop | M22: Awaiting order request
B23: CP Plus | C23: 4 MP Bullet IP Camera - CP Plus | E23: CP-UNC-TA41L3C- | F23: 4860 | J23: Position marked - I | L23: Prop | M23: Awaiting order request
B24: CP Plus | C24: 4 MP Bullet IP Camera - CP Plus | E24: CP-UNC-TA41L3C- | F24: 4860 | J24: Position marked - I | L24: Prop | M24: Awaiting order request
B25: CP Plus | C25: 4 MP Dome IP Camera - CP Plus | E25: CP-UNC-DA41PL3C | F25: 4050 | J25: Position marked - I | L25: Prop | M25: Awaiting order request
B26: CP Plus | C26: 16 Channel NVR - CP Plus | E26: CP-UNR4K- 4162-V2 | F26: 15500 | J26: Position marked - I | L26: Prop | M26: Awaiting order request
B27: TP Link | C27: 16 Port POE Gigabit Switch (TL-SG1218MPE) - TP Link | E27: TL-SG1218MPE | F27: 15625 | J27: Position marked - I | L27: Prop | M27: Awaiting order request
B28: Toshiba | C28: 4 TB Hard Disk - Toshiba | E28: AVHDDS300 | F28: 8160 | J28: Position marked - I | L28: Prop | M28: Awaiting order request
C29: Camera Accessories | F29: 2500
A31: Security Alarm System - DSC TYCO | B31: DSC TYCO | C31: DSC Hybrid - Control Panel | E31: HS2032NKCE | F31: 22450 | G31: 17905 | J31: Position marked - I | L31: Prop | M31: Awaiting order request
B32: DSC TYCO | C32: DSC - LCD Keypad Kit | E32: HS2LCDS | F32: 5900 | J32: Position marked - I | L32: Prop | M32: Awaiting order request
B33: DSC TYCO | C33: DSC - Power Supply (220V CE Transformer) | E33: 220-16.5V TRF | F33: 2808 | J33: Position marked - I | L33: Prop | M33: Awaiting order request
B34: Securico | C34: Door Sensor (Mag) - Wired | E34: SEC-MSC | F34: 450 | J34: Position marked - I | L34: Prop | M34: Awaiting order request
B35: Securico | C35: Door Sensor (Mag) - Wired | E35: SEC-MSC | F35: 450 | J35: Position marked - I | L35: Prop | M35: Awaiting order request
B36: Securico | C36: Door Sensor (Mag) - Wired | E36: SEC-MSC | F36: 450 | J36: Position marked - I | L36: Prop | M36: Awaiting order request
B37: DSC TYCO | C37: DSC - Wired Vibration/Shock Sensor | E37: SS-102 | F37: 4100 | J37: Position marked - I | L37: Prop | M37: Awaiting order request
B38: DSC TYCO | C38: DSC - Wired Vibration/Shock Sensor | E38: SS-102 | F38: 4100 | J38: Position marked - I | L38: Prop | M38: Awaiting order request
B39: DSC TYCO | C39: DSC - Wired Vibration/Shock Sensor | E39: SS-102 | F39: 4100 | J39: Position marked - I | L39: Prop | M39: Awaiting order request
B40: DSC TYCO | C40: DSC - Wired Vibration/Shock Sensor | E40: SS-102 | F40: 4100 | J40: Position marked - I | L40: Prop | M40: Awaiting order request
B41: DSC TYCO | C41: DSC - Wired Vibration/Shock Sensor | E41: SS-102 | F41: 4100 | J41: Position marked - I | L41: Prop | M41: Awaiting order request
...

Sheet Karunanidhi Construction
B1: Client Name | C1: Karunanidhi Construction | D1: Mrs. Thrisha | E1: 9003105327 | F1: Overall site status | J1: Count | K1: % | M1: Material status | N1: Count | O1: % | Q1: Visti No. | R1: IR No. | S1: Date
B2: Site | C2: SB Colony | F2: Yet to start | M2: Awaiting order request | Q2: 1 | S2: 7.11.2025 | T2: 1st site visit | U2: Kumaraguru
B3: Location | F3: Position marked - I | M3: To order material | Q3: 2 | S3: 10.11.2025 | T3: installation | U3: sakthi & Kumaraguru
B4: GPS Coordinates | F4: Piping done - C | M4: Ordered
B5: Architect | F5: Wiring done - C | M5: Recd (To test/config)
B6: Site Supervisor | C6: Mr. Boobesh viswanathan | E6: 8526903777 | F6: Wiring - Checked Ok - I | M6: Configured - ready for install
B7: Electrician | F7: Wiring rework reqd - C | M7: Delivered
B8: Electrical Contractor | F8: Provision not provided - C | M8: Provision only - Matl Not reqd
B9: Billing contact | F9: Position to be changed - C | M9: Failed - Picked up from site
B10: Carpenter | F10: Installed - working | M10: Failed - Need to service
B11: Civil Supervisor | F11: Installed - To activate - I | M11: Sent for service
B12: G-Drive Link | F12: Installed - Not working - IC | M12: Replaced/Serviced
B13: Mail id | F13: Door Ready - C | M13: Returned - Not reqd
B14: Site Engineer | F14: Door Not Ready - I
B15: Brand | C15: Product | D15: Serial No. | E15: Model No | F15: Sale Price | G15: Installation charge | H15: Location | I15: Drawing Ref No. | J15: Site status | K15: <--Date | L15: Prop/Addl | M15: Material | N15: <-- Date | O15: Client | P15: Inka | Q15: Comments | R15: SR Nos (If multiple - add all) | S15: DC
A16: Camera | B16: CP Plus | C16: 4 MP Bullet IP Camera - CP Plus | E16: CP-UNC-TB41L3-MDS | F16: 4860 | G16: 4074 | J16: Installed - working | K16: 45941 | L16: Prop | M16: Delivered | N16: 5.11.2025 | S16: 177
B17: CP Plus | C17: 4 MP Bullet IP Camera - CP Plus | E17: CP-UNC-TB41L3-MDS | F17: 4860 | J17: Installed - working | K17: 45941 | L17: Prop | M17: Delivered | N17: 5.11.2025 | S17: 177
B18: CP Plus | C18: 4 MP Bullet IP Camera - CP Plus | E18: CP-UNC-TB41L3-MDS | F18: 4860 | J18: Installed - working | K18: 45941 | L18: Prop | M18: Delivered | N18: 5.11.2025 | S18: 177
B19: CP Plus | C19: 4 MP Bullet IP Camera - CP Plus | E19: CP-UNC-TB41L3-MDS | F19: 4860 | J19: Installed - working | K19: 45941 | L19: Prop | M19: Delivered | N19: 5.11.2025 | S19: 177
B20: TP Link | C20: 8 Port POE Switch (Gigabit) 2 Uplink SFP - TP Link | E20: TL-SG2210P | F20: 7990 | J20: Installed - working | K20: 45941 | L20: Prop | M20: Delivered | N20: 5.11.2025 | S20: 177
B21: CP Plus | C21: 4 Channal NVR - CP Plus / 1 Sata | E21: CP-UNR-104F1 | F21: 4250 | J21: Installed - working | K21: 45941 | L21: Prop | M21: Delivered | N21: 5.11.2025 | S21: 177
B22: Toshiba | C22: 4 TB Hard Disk - Toshiba | E22: AVHDDS300 | F22: 8160 | J22: Installed - working | K22: 45941 | L22: Prop | M22: Delivered | N22: 5.11.2025 | S22: 177
C23: Camera Accessories | F23: 900 | J23: Installed - working | K23: 45941 | L23: Prop | M23: Delivered | N23: 5.11.2025 | S23: 177
B24: CP Plus | C24: 2U RACK-CP PLUS | E24: RK4535VW-2U | J24: Installed - working | K24: 45941 | L24: Addl | M24: Delivered | N24: 5.11.2025 | S24: 177
C25: 3 Module Plate (4x4G Wood Sheet) | E25: 4X4 G | J25: Installed - working | K25: 45941 | L25: Addl | M25: Delivered | N25: 5.11.2025 | S25: 177
C26: 3 Module Plate (4x4G Wood Sheet) | E26: 4X4 G | J26: Installed - working | K26: 45941 | L26: Addl | M26: Delivered | N26: 5.11.2025 | S26: 177
C27: 3 Module Plate (4x4G Wood Sheet) | E27: 4X4 G | J27: Installed - working | K27: 45941 | L27: Addl | M27: Delivered | N27: 5.11.2025 | S27: 177
C28: 3 Module Plate (4x4G Wood Sheet) | E28: 4X4 G | J28: Installed - working | K28: 45941 | L28: Addl | M28: Delivered | N28: 5.11.2025 | S28: 177

Sheet Race Course Apartment
B1: Client Name | C1: Race Course Apartment - Mr. Vengateswaran | F1: Overall site status | J1: Count | K1: % | M1: Material status | N1: Count | O1: % | Q1: Visti No. | R1: IR No. | S1: Date
B2: Site | C2: Race Course | F2: Yet to start | M2: Awaiting order request | Q2: 1 | S2: 14.10.2025 | T2: 1st site visit | U2: Kumaraguru
B3: Location | F3: Position marked - I | M3: To order material | Q3: 2 | S3: 15.10.2025 | T3: installation | U3: sakthi & Kumaraguru
B4: GPS Coordinates | F4: Piping done - C | M4: Ordered
B5: Architect | C5: Ar. Neeraj Sivakumar | E5: 7904076275 | F5: Wiring done - C | M5: Recd (To test/config)
B6: Site Supervisor | F6: Wiring - Checked Ok - I | M6: Configured - ready for install
B7: Electrician | F7: Wiring rework reqd - C | M7: Delivered
B8: Electrical Contractor | F8: Provision not provided - C | M8: Provision only - Matl Not reqd
B9: Billing contact | F9: Position to be changed - C | M9: Failed - Picked up from site
B10: Carpenter | F10: Installed - working | M10: Failed - Need to service
B11: Civil Supervisor | F11: Installed - To activate - I | M11: Sent for service
B12: G-Drive Link | F12: Installed - Not working - IC | M12: Replaced/Serviced
B13: Mail id | F13: Door Ready - C | M13: Returned - Not reqd
B14: Site Engineer | F14: Door Not Ready - I
B15: Brand | C15: Product | D15: Serial No. | E15: Model No | F15: Sale Price | G15: Installation charge | H15: Location | I15: Drawing Ref No. | J15: Site status | K15: <--Date | L15: Prop/Addl | M15: Material | N15: <-- Date | O15: Client | P15: Inka | Q15: Comments | R15: SR Nos (If multiple - add all) | S15: DC
A16: Camera | B16: CP Plus | C16: 4 MP WIFI WIRELESS CAMERA -CP PLUS | D16: 240101320003932 | E16: CP-V41A | F16: 2600 | G16: 3500 | J16: Installed - working | K16: 7.11.2025 | L16: Prop | M16: Delivered | S16: 178
B17: Sandisk | C17: Memory Card 256GB - Sandisk | E17: 256 GB | F17: 2190 | J17: Installed - working | K17: 7.11.2025 | L17: Prop | M17: Delivered | S17: 178
A19: VDP | B19: Hikvision | C19: VDP Indoor Monitor- Hikvision | D19: WIRELESS-Q41041931 | E19: DS-KH6320-WTE1 | F19: 14500 | J19: Installed - working | K19: 7.11.2025 | L19: Prop | M19: Delivered | S19: 178
C20: VDP Outdoor Camera - Hikvision | D20: WIRELESS-GC3153630 | E20: DS-KD6113 | J20: Installed - working | K20: 7.11.2025 | L20: Prop | M20: Delivered | S20: 178
C21: Camera Accessories | F21: 1000
A23: Wifi | B23: TP Link | C23: Access Point EAP245 - TP Link | D23: 224B152004485 | E23: EAP245 | F23: 8250 | G23: 1500 | L23: Addl | M23: Delivered | N23: 11.11.2025 | S23: 182
C24: Cat 6 Cable - Netfox-7mts | F24: 294 | L24: Addl | M24: Delivered | N24: 11.11.2025 | S24: 182

Sheet Mohan Atirum House
B1: Client Name | C1: Mohan Atrium House | D1: Mr. Naveen | F1: Overall site status | J1: Count | K1: % | M1: Material status | N1: Count | O1: % | Q1: Visti No. | R1: IR No. | S1: Date
B2: Site | C2: Sulur | F2: Yet to start | M2: Awaiting order request | Q2: 1 | R2: IR No.206 | S2: 3.7.2025 | T2: 1st site visit | U2: Sakthi
B3: Location | F3: Position marked - I | M3: To order material | Q3: 2 | R3: IR No.231 | S3: 10.7.2025 | T3: Site meeting | U3: Sakthi
B4: GPS Coordinates | F4: Piping done - C | M4: Ordered | Q4: 3 | R4: IR No.236 | S4: 21.7.2025 | T4: Site meeting | U4: Sakthi
B5: Architect | F5: Wiring done - C | M5: Recd (To test/config) | Q5: 4 | R5: IR No.1446 | S5: 25.7.2025 | T5: Piping checking | U5: Sakthi
B6: Site Supervisor | F6: Wiring - Checked Ok - I | M6: Configured - ready for install
B7: Electrician | F7: Wiring rework reqd - C | M7: Delivered
B8: Electrical Contractor | F8: Provision not provided - C | M8: Provision only - Matl Not reqd
B9: Billing contact | F9: Position to be changed - C | M9: Failed - Picked up from site
B10: Carpenter | F10: Installed - working | M10: Failed - Need to service
B11: Civil Supervisor | F11: Installed - To activate - I | M11: Sent for service
B12: G-Drive Link | F12: Installed - Not working - IC | M12: Replaced/Serviced
B13: Mail id | F13: Door Ready - C | M13: Returned - Not reqd
B14: Site Engineer | F14: Door Not Ready - I
B15: Brand | C15: Product | D15: Serial No. | E15: Model No | F15: Sale Price | G15: Installation charge | H15: Location | I15: Drawing Ref No. | J15: Site status | K15: <--Date | L15: Prop/Addl | M15: Material | N15: <-- Date | O15: Client | P15: Inka | Q15: Comments | R15: SR Nos (If multiple - add all) | S15: DC
A16: Camera | B16: Prama | C16: 4 Mp Bullet IP Camera Colour/InbuiltMic - Prama | E16: PT-NC140D3LIU(D2) | F16: 4840 | G16: 12037 | L16: Prop
B17: Prama | C17: 4 Mp Bullet IP Camera Colour/InbuiltMic - Prama | E17: PT-NC140D3LIU(D2) | F17: 4840 | L17: Prop
B18: Prama | C18: 4 Mp Bullet IP Camera Colour/InbuiltMic - Prama | E18: PT-NC140D3LIU(D2) | F18: 4840 | L18: Prop
B19: Prama | C19: 4 Mp Bullet IP Camera Colour/InbuiltMic - Prama | E19: PT-NC140D3LIU(D2) | F19: 4840 | L19: Prop
B20: Prama | C20: 4 Mp Bullet IP Camera Colour/InbuiltMic - Prama | E20: PT-NC140D3LIU(D2) | F20: 4840 | L20: Prop
B21: Prama | C21: 4 Mp Bullet IP Camera Colour/InbuiltMic - Prama | E21: PT-NC140D3LIU(D2) | F21: 4840 | L21: Prop
B22: Prama | C22: 4 Mp Bullet IP Camera Colour/InbuiltMic - Prama | E22: PT-NC140D3LIU(D2) | F22: 4840 | L22: Prop
B23: Prama | C23: 4 Mp Bullet IP Camera Colour/InbuiltMic - Prama | E23: PT-NC140D3LIU(D2) | F23: 4840 | L23: Prop
B24: Prama | C24: 4 Mp Bullet IP Camera Colour/InbuiltMic - Prama | E24: PT-NC140D3LIU(D2) | F24: 4840 | L24: Prop
B25: Prama | C25: 4 Mp Bullet IP Camera Colour/InbuiltMic - Prama | E25: PT-NC140D3LIU(D2) | F25: 4840 | L25: Prop
B26: Prama | C26: 4 Mp Bullet IP Camera Colour/InbuiltMic - Prama | E26: PT-NC140D3LIU(D2) | F26: 4840 | L26: Prop
B27: Prama | C27: 4 Mp Bullet IP Camera Colour/InbuiltMic - Prama | E27: PT-NC140D3LIU(D2) | F27: 4840 | L27: Prop
B28: Prama Hikvision | C28: 16 Channel NVR (K2) - Prama Hikvision | E28: PT-NRAS2A16-K2 | F28: 14500 | L28: Prop
... B31: Netfox | C31: Cat 6 Jack - Netfox-35 nos. | E31: RJ-45 | F31: 25 | L31: Prop
C32: Camera Accessories | F32: 2050 | L32: Prop
L33: Prop
A34: Security Alarm System - DSC TYCO | B34: DSC | C34: DSC Hybrid - Control Panel | E34: HS2032NKCE | F34: 24450 | G34: 22989
B35: DSC | C35: DSC - LCD Keypad Kit | E35: HS2LCDS | F35: 6300 | L35: Prop
B36: DSC | C36: DSC - Power Supply (220V CE Transformer) | E36: 220-16.5V TRF | F36: 2808 | L36: Prop
B37: Securico | C37: Door Sensor (Mag) - Wired | E37: SEC-MSC | F37: 450 | L37: Prop
B38: Securico | C38: Door Sensor (Mag) - Wired | E38: SEC-MSC | F38: 450 | L38: Prop
B39: Securico | C39: Door Sensor (Mag) - Wired | E39: SEC-MSC | F39: 450 | L39: Prop
B40: Securico | C40: Door Sensor (Mag) - Wired | E40: SEC-MSC | F40: 450 | L40: Prop
B41: Securico | C41: Door Sensor (Mag) - Wired | E41: SEC-MSC | F41: 450 | L41: Prop
B42: Securico | C42: Door Sensor (Mag) - Wired | E42: SEC-MSC | F42: 450 | L42: Prop
...

Sheet NavBalu Associates
B1: Client Name | C1: NavBalu Associates | D1: Mr. Naveen | E1: 8015161702 | F1: Overall site status | J1: Count | K1: % | M1: Material status | N1: Count | O1: % | Q1: Visti No. | R1: IR No. | S1: Date
B2: Site | C2: 100 ft road | F2: Yet to start | M2: Awaiting order request | Q2: 1 | S2: 14.10.2025 | T2: 1st site visit | U2: Kumaraguru
B3: Location | C3: https://maps.app.goo.gl/fsNtNaE3TBK9fQcZ6?g_st=awb | F3: Position marked - I | M3: To order material | Q3: 2 | S3: 15.10.2025 | T3: installation | U3: sakthi & Kumaraguru
B4: GPS Coordinates | F4: Piping done - C | M4: Ordered
B5: Architect | F5: Wiring done - C | M5: Recd (To test/config)
B6: Site Supervisor | F6: Wiring - Checked Ok - I | M6: Configured - ready for install
B7: Electrician | F7: Wiring rework reqd - C | M7: Delivered
B8: Electrical Contractor | F8: Provision not provided - C | M8: Provision only - Matl Not reqd
B9: Billing contact | F9: Position to be changed - C | M9: Failed - Picked up from site
B10: Carpenter | F10: Installed - working | M10: Failed - Need to service
B11: Civil Supervisor | F11: Installed - To activate - I | M11: Sent for service
B12: G-Drive Link | F12: Installed - Not working - IC | M12: Replaced/Serviced
B13: Mail id | F13: Door Ready - C | M13: Returned - Not reqd
B14: Site Engineer | F14: Door Not Ready - I
B15: Brand | C15: Product | D15: Serial No. | E15: Model No | F15: Sale Price | G15: Installation charge | H15: Location | I15: Drawing Ref No. | J15: Site status | K15: <--Date | L15: Prop/Addl | M15: Material | N15: <-- Date | O15: Client | P15: Inka | Q15: Comments | R15: SR Nos (If multiple - add all) | S15: DC
A16: Security system | B16: Hikvision | C16: Hikvision - Control Panel AX Pro | E16: DS-PWA64 - AX Pro | F16: 27450 | G16: 7090 | H16: MD Room | J16: Completed | K16: 15.10.2025 | L16: Prop | M16: Delivered | N16: 15.10.2025 | S16: 169
B17: Hikvision | C17: Hikvision - Wireless Dual Sensor (Door/Vibration) | D17: Q36721906 | E17: PDMCK-EG2-WB | F17: 4750 | H17: MD room inside | J17: Completed | K17: 15.10.2025 | L17: Prop | M17: Delivered | N17: 15.10.2025 | S17: 169
B18: Hikvision | C18: Hikvision - Wireless Dual Sensor (Door/Vibration) | D18: Q36721882 | E18: PDMCK-EG2-WB | F18: 4750 | H18: MD room outside | J18: Completed | K18: 15.10.2025 | L18: Prop | M18: Delivered | N18: 15.10.2025 | S18: 169
B19: Hikvision | C19: Hikvision - Wireless Dual Sensor (Door/Vibration) | D19: Q41058404 | E19: PDMCK-EG2-WB | F19: 4750 | H19: Work space window 1 | J19: Completed | K19: 15.10.2025 | L19: Prop | M19: Delivered | N19: 15.10.2025 | S19: 169
B20: Hikvision | C20: Wireless Magnetic Door Sensor - Hikvision | D20: Q39151332 | E20: DS-PD1-MC-WWS | F20: 2950 | H20: Front entrance door | J20: Completed | K20: 15.10.2025 | L20: Prop | M20: Delivered | N20: 15.10.2025 | S20: 169
B21: Hikvision | C21: Wireless Magnetic Door Sensor - Hikvision | D21: Q39151335 | E21: DS-PD1-MC-WWS | F21: 2950 | H21: Back Exit door | J21: Completed | K21: 15.10.2025 | L21: Prop | M21: Delivered | N21: 15.10.2025 | S21: 169
B22: Hikvision | C22: Wireless Magnetic Door Sensor - Hikvision | D22: Q39151361 | E22: DS-PD1-MC-WWS | F22: 2950 | H22: Work space window 2 | J22: Completed | K22: 15.10.2025 | L22: Prop | M22: Delivered | N22: 15.10.2025 | S22: 169
B23: Hikvision | C23: Wireless Magnetic Door Sensor - Hikvision | D23: Q39151362 | E23: DS-PD1-MC-WWS | F23: 2950 | H23: Work space window 3 | J23: Completed | K23: 15.10.2025 | L23: Prop | M23: Delivered | N23: 15.10.2025 | S23: 169
B24: Hikvision | C24: Wireless Magnetic Door Sensor - Hikvision | D24: Q39151387 | E24: DS-PD1-MC-WWS | F24: 2950 | H24: Work space window entry | J24: Completed | K24: 15.10.2025 | L24: Prop | M24: Delivered | N24: 15.10.2025 | S24: 169
B25: Hikvision | C25: Wireless Magnetic Door Sensor - Hikvision | D25: Q39151364 | E25: DS-PD1-MC-WWS | F25: 2950 | H25: Work space window exit | J25: Completed | K25: 15.10.2025 | L25: Prop | M25: Delivered | N25: 15.10.2025 | S25: 169
B26: Hikvision | C26: Key fob (Wireless ) | D26: Q31168017 | E26: WS4939 | F26: 2200 | J26: Completed | K26: 15.10.2025 | L26: Prop | M26: Delivered | N26: 15.10.2025 | S26: 169
B27: Hikvision | C27: Key fob (Wireless ) | D27: Q31167996 | E27: WS4939 | F27: 2200 | J27: Completed | K27: 15.10.2025 | L27: Prop | M27: Delivered | N27: 15.10.2025 | S27: 169
B28: Hikvision | C28: Wireless Siren - Hikvision | D28: Q40780281 | E28: Wireless Siren | F28: 7100 | H28: Car parking | J28: Completed | K28: 15.10.2025 | L28: Prop | M28: Delivered | N28: 15.10.2025 | S28: 169

Sheet Arrow Hospital
B1: Client Name | C1: Arrow Hospital | D1: Mr.Haseeb | E1: 9443020343 | F1: Overall site status | J1: Count | K1: % | M1: Material status | N1: Count | O1: % | Q1: Visti No. | R1: IR No. | S1: Date
B2: Site | C2: Vadavalli | E2: 9688748946 | F2: Yet to start | M2: Awaiting order request
B3: Location | E3: 9840706220 | F3: Position marked - I | M3: To order material
B4: GPS Coordinates | F4: Piping done - C | M4: Ordered
B5: Architect | F5: Wiring done - C | M5: Recd (To test/config)
B6: Site Supervisor | F6: Wiring - Checked Ok - I | M6: Configured - ready for install
B7: Electrician | F7: Wiring rework reqd - C | M7: Delivered
B8: Electrical Contractor | F8: Provision not provided - C | M8: Provision only - Matl Not reqd
B9: Billing contact | F9: Position to be changed - C | M9: Failed - Picked up from site
B10: Carpenter | F10: Installed - working | M10: Failed - Need to service
B11: Civil Supervisor | F11: Installed - To activate - I | M11: Sent for service
B12: G-Drive Link | F12: Installed - Not working - IC | M12: Replaced/Serviced
B13: Mail id | F13: Door Ready - C | M13: Returned - Not reqd
B14: Site Engineer | F14: Door Not Ready - I
B16: Brand | C16: Product | D16: Serial No. | E16: Model No | F16: Sale Price | G16: Installation charge | H16: Location | I16: Drawing Ref No. | J16: Site status | K16: <--Date | L16: Prop/Addl | M16: Material | N16: <-- Date | O16: Client | P16: Inka | Q16: Comments | R16: SR Nos (If multiple - add all) | S16: DC
A17: Camera | B17: Prama Hivision | C17: 4 MP Bullet IP Camera | E17: PT-NC140D3-IUF(D) | F17: 4250 | G17: 42500 | J17: Yet to start | L17: Prop | M17: Awaiting order request | Q17: 1st site visit done
B18: Prama Hivision | C18: 4 MP Bullet IP Camera | E18: PT-NC140D3-IUF(D) | F18: 4250 | J18: Yet to start | L18: Prop | M18: Awaiting order request | Q18: 1st site visit done
B19: Prama Hivision | C19: 4 MP Bullet IP Camera | E19: PT-NC140D3-IUF(D) | F19: 4250 | J19: Yet to start | L19: Prop | M19: Awaiting order request | Q19: 1st site visit done
B20: Prama Hivision | C20: 4 MP Bullet IP Camera | E20: PT-NC140D3-IUF(D) | F20: 4250 | J20: Yet to start | L20: Prop | M20: Awaiting order request | Q20: 1st site visit done
B21: Prama Hivision | C21: 4 MP Bullet IP Camera | E21: PT-NC140D3-IUF(D) | F21: 4250 | J21: Yet to start | L21: Prop | M21: Awaiting order request | Q21: 1st site visit done
B22: Prama Hivision | C22: 4 MP Bullet IP Camera | E22: PT-NC140D3-IUF(D) | F22: 4250 | J22: Yet to start | L22: Prop | M22: Awaiting order request | Q22: 1st site visit done
B23: Prama Hivision | C23: 4 MP Bullet IP Camera | E23: PT-NC140D3-IUF(D) | F23: 4250 | J23: Yet to start | L23: Prop | M23: Awaiting order request | Q23: 1st site visit done
B24: Prama Hivision | C24: 4 MP Bullet IP Camera | E24: PT-NC140D3-IUF(D) | F24: 4250 | J24: Yet to start | L24: Prop | M24: Awaiting order request | Q24: 1st site visit done
B25: Prama Hivision | C25: 4 MP Bullet IP Camera | E25: PT-NC140D3-IUF(D) | F25: 4250 | J25: Yet to start | L25: Prop | M25: Awaiting order request | Q25: 1st site visit done
B26: Prama Hivision | C26: 4 MP Bullet IP Camera | E26: PT-NC140D3-IUF(D) | F26: 4250 | J26: Yet to start | L26: Prop | M26: Awaiting order request | Q26: 1st site visit done
B27: Prama Hivision | C27: 4 MP Dome IP Camera Colour/InbuiltMic - Prama | E27: PT-NC143D3LIU(D2) | F27: 4250 | J27: Yet to start | L27: Prop | M27: Awaiting order request | Q27: 1st site visit done
B28: Prama Hivision | C28: 4 MP Dome IP Camera Colour/InbuiltMic - Prama | E28: PT-NC143D3LIU(D2) | F28: 4250 | J28: Yet to start | L28: Prop | M28: Awaiting order request | Q28: 1st site visit done
B29: Prama Hivision | C29: 4 MP Dome IP Camera Colour/InbuiltMic - Prama | E29: PT-NC143D3LIU(D2) | F29: 4250 | J29: Yet to start | L29: Prop | M29: Awaiting order request | Q29: 1st site visit done
... B75: Toshiba | C75: 8 TB Hard Disk - Toshiba | E75: Nil | F75: 18450 | J75: Yet to start | L75: Prop | M75: Awaiting order request | Q75: 1st site visit done
C76: Camera Accessories | F76: 4500
A78: Networking | B78: Grandstream | C78: IPBX Gradstream UCM 6301 | E78: UCM6301 | F78: 36400 | G78: 13280 | J78: Yet to start | L78: Prop | M78: Awaiting order request | Q78: 1st site visit done
B79: TP Link | C79: 24 Port Switch (Gigabit) - TP Link | E79: SG3428D | F79: 15500 | J79: Yet to start | L79: Prop | M79: Awaiting order request | Q79: 1st site visit done
B80: Grandstream | C80: IP Phone (GRP2601) - Grand stream | E80: GRP2601 | F80: 69350
B81: Grandstream | C81: IP Phone GRP2615 | E81: GRP 2615 | F81: 11550
A83: Wifi | B83: TP Link | C83: Access Point EAP245 - TP Link | E83: EAP245 | F83: 8250 | G83: 26340 | J83: Yet to start | L83: Prop | M83: Awaiting order request | Q83: 1st site visit done
B84: TP Link | C84: Access Point EAP245 - TP Link | E84: EAP245 | F84: 8250 | J84: Yet to start | L84: Prop | M84: Awaiting order request | Q84: 1st site visit done
B85: TP Link | C85: Access Point EAP245 - TP Link | E85: EAP245 | F85: 8250 | J85: Yet to start | L85: Prop | M85: Awaiting order request | Q85: 1st site visit done
B86: TP Link | C86: Access Point EAP245 - TP Link | E86: EAP245 | F86: 8250 | J86: Yet to start | L86: Prop | M86: Awaiting order request | Q86: 1st site visit done
B87: TP Link | C87: Access Point EAP245 - TP Link | E87: EAP245 | F87: 8250 | J87: Yet to start | L87: Prop | M87: Awaiting order request | Q87: 1st site visit done
B88: TP Link | C88: Access Point EAP245 - TP Link | E88: EAP245 | F88: 8250 | J88: Yet to start | L88: Prop | M88: Awaiting order request | Q88: 1st site visit done
...

Sheet Raghukumaran
B1: Client Name | C1: Mr. Raghukumaran | E1: 9751739555 | F1: Overall site status | J1: Count | K1: % | M1: Material status | N1: Count | O1: % | Q1: Visti No. | R1: IR No. | S1: Date
